Fetching weather data...
Database connection successful.
Data successfully pushed to weather table.
Weather data fetched successfully!
Fetching flight data...
Database connection successful.
Traceback (most recent call last):
  File "/home/graviton/.local/lib/python3.10/site-packages/requests/models.py", line 974, in json
    return complexjson.loads(self.text, **kwargs)
  File "/usr/lib/python3.10/json/__init__.py", line 346, in loads
    return _default_decoder.decode(s)
  File "/usr/lib/python3.10/json/decoder.py", line 337, in decode
    obj, end = self.raw_decode(s, idx=_w(s, 0).end())
  File "/usr/lib/python3.10/json/decoder.py", line 355, in raw_decode
    raise JSONDecodeError("Expecting value", s, err.value) from None
json.decoder.JSONDecodeError: Expecting value: line 1 column 1 (char 0)

During handling of the above exception, another exception occurred:

Traceback (most recent call last):
  File "/home/graviton/PROGRAM/gitRepo/Data-Engineering/main.py", line 158, in <module>
    main(fetch_weather=args.weather, fetch_flights=args.flights)
  File "/home/graviton/PROGRAM/gitRepo/Data-Engineering/main.py", line 142, in main
    fetch_and_store_flights(engine, icao_list)
  File "/home/graviton/PROGRAM/gitRepo/Data-Engineering/main.py", line 111, in fetch_and_store_flights
    flights_to_db = get_flight_data(icao_list)
  File "/home/graviton/PROGRAM/gitRepo/Data-Engineering/data/flight.py", line 83, in get_flight_data
    flights_json = response.json()
  File "/home/graviton/.local/lib/python3.10/site-packages/requests/models.py", line 978, in json
    raise RequestsJSONDecodeError(e.msg, e.doc, e.pos)
requests.exceptions.JSONDecodeError: Expecting value: line 1 column 1 (char 0)
Flight data fetched successfully!
